{"trial_id": "0", "hyperparameters": {"space": [{"class_name": "Int", "config": {"name": "num_dense_layers", "default": null, "conditions": [], "min_value": 2, "max_value": 5, "step": 1, "sampling": "linear"}}, {"class_name": "Float", "config": {"name": "dropout_0", "default": 0.0, "conditions": [], "min_value": 0.0, "max_value": 0.5, "step": 0.1, "sampling": "linear"}}, {"class_name": "Int", "config": {"name": "layer_0", "default": null, "conditions": [], "min_value": 32, "max_value": 1024, "step": 64, "sampling": "linear"}}, {"class_name": "Choice", "config": {"name": "act_0", "default": "relu", "conditions": [], "values": ["relu", "sigmoid"], "ordered": false}}, {"class_name": "Float", "config": {"name": "dropout_1", "default": 0.0, "conditions": [], "min_value": 0.0, "max_value": 0.5, "step": 0.1, "sampling": "linear"}}, {"class_name": "Int", "config": {"name": "layer_1", "default": null, "conditions": [], "min_value": 32, "max_value": 1024, "step": 64, "sampling": "linear"}}, {"class_name": "Choice", "config": {"name": "act_1", "default": "relu", "conditions": [], "values": ["relu", "sigmoid"], "ordered": false}}, {"class_name": "Choice", "config": {"name": "learning_rate", "default": 0.1, "conditions": [], "values": [0.1, 0.01, 0.001, 0.0001], "ordered": true}}], "values": {"num_dense_layers": 2, "dropout_0": 0.4, "layer_0": 352, "act_0": "sigmoid", "dropout_1": 0.0, "layer_1": 992, "act_1": "relu", "learning_rate": 0.1}}, "metrics": {"metrics": {}}, "score": null, "best_step": 0, "status": "FAILED", "message": "Traceback (most recent call last):\n  File \"c:\\Python\\Python39\\lib\\site-packages\\keras_tuner\\engine\\base_tuner.py\", line 266, in _try_run_and_update_trial\n    self._run_and_update_trial(trial, *fit_args, **fit_kwargs)\n  File \"c:\\Python\\Python39\\lib\\site-packages\\keras_tuner\\engine\\base_tuner.py\", line 231, in _run_and_update_trial\n    results = self.run_trial(trial, *fit_args, **fit_kwargs)\n  File \"c:\\Python\\Python39\\lib\\site-packages\\keras_tuner\\engine\\tuner.py\", line 287, in run_trial\n    obj_value = self._build_and_fit_model(trial, *args, **copied_kwargs)\n  File \"c:\\Python\\Python39\\lib\\site-packages\\keras_tuner\\engine\\tuner.py\", line 214, in _build_and_fit_model\n    results = self.hypermodel.fit(hp, model, *args, **kwargs)\n  File \"c:\\Python\\Python39\\lib\\site-packages\\keras_tuner\\engine\\hypermodel.py\", line 144, in fit\n    return model.fit(*args, **kwargs)\n  File \"c:\\Python\\Python39\\lib\\site-packages\\keras\\utils\\traceback_utils.py\", line 70, in error_handler\n    raise e.with_traceback(filtered_tb) from None\n  File \"C:\\Users\\jack_\\AppData\\Local\\Temp\\__autograph_generated_filetwt4lk6_.py\", line 15, in tf__train_function\n    retval_ = ag__.converted_call(ag__.ld(step_function), (ag__.ld(self), ag__.ld(iterator)), None, fscope)\nValueError: in user code:\n\n    File \"c:\\Python\\Python39\\lib\\site-packages\\keras\\engine\\training.py\", line 1284, in train_function  *\n        return step_function(self, iterator)\n    File \"c:\\Python\\Python39\\lib\\site-packages\\keras\\engine\\training.py\", line 1268, in step_function  **\n        outputs = model.distribute_strategy.run(run_step, args=(data,))\n    File \"c:\\Python\\Python39\\lib\\site-packages\\keras\\engine\\training.py\", line 1249, in run_step  **\n        outputs = model.train_step(data)\n    File \"c:\\Python\\Python39\\lib\\site-packages\\keras\\engine\\training.py\", line 1055, in train_step\n        return self.compute_metrics(x, y, y_pred, sample_weight)\n    File \"c:\\Python\\Python39\\lib\\site-packages\\keras\\engine\\training.py\", line 1149, in compute_metrics\n        self.compiled_metrics.update_state(y, y_pred, sample_weight)\n    File \"c:\\Python\\Python39\\lib\\site-packages\\keras\\engine\\compile_utils.py\", line 577, in update_state\n        self.build(y_pred, y_true)\n    File \"c:\\Python\\Python39\\lib\\site-packages\\keras\\engine\\compile_utils.py\", line 483, in build\n        self._metrics = tf.__internal__.nest.map_structure_up_to(\n    File \"c:\\Python\\Python39\\lib\\site-packages\\keras\\engine\\compile_utils.py\", line 631, in _get_metric_objects\n        return [self._get_metric_object(m, y_t, y_p) for m in metrics]\n    File \"c:\\Python\\Python39\\lib\\site-packages\\keras\\engine\\compile_utils.py\", line 631, in <listcomp>\n        return [self._get_metric_object(m, y_t, y_p) for m in metrics]\n    File \"c:\\Python\\Python39\\lib\\site-packages\\keras\\engine\\compile_utils.py\", line 650, in _get_metric_object\n        metric_obj = metrics_mod.get(metric)\n    File \"c:\\Python\\Python39\\lib\\site-packages\\keras\\metrics\\__init__.py\", line 204, in get\n        return deserialize(str(identifier))\n    File \"c:\\Python\\Python39\\lib\\site-packages\\keras\\metrics\\__init__.py\", line 158, in deserialize\n        return deserialize_keras_object(\n    File \"c:\\Python\\Python39\\lib\\site-packages\\keras\\saving\\legacy\\serialization.py\", line 543, in deserialize_keras_object\n        raise ValueError(\n\n    ValueError: Unknown metric function: 'val_loss'. Please ensure you are using a `keras.utils.custom_object_scope` and that this object is included in the scope. See https://www.tensorflow.org/guide/keras/save_and_serialize#registering_the_custom_object for details.\n\n"}